Workbook

Sheet Assumptions
A1: Shared Assumptions and Equivalency Factors
A3: Mission Parameters
A4: Parameter | B4: Value | C4: Unit | E4: Legend
A5: Crew size | B5: 6 | C5: crew members | E5: User-editable cell
A6: Mission surface duration | B6: =+B7*7 -> 602 | C6: days | E6: Not applicable / No data
A7: Mission duration (weeks) | B7: 86 | C7: weeks
A8: Base case dose | B8: 5 | C8: mg PTH-Fc/CM/week
A9: Total mission dose per CM | B9: =B7*B8 -> 430 | C9: mg PTH-Fc/CM/mission
A11: 2022 Baseline Values and Assumptions
A12: Parameter | B12: Volume (kgeq/m3) | C12: Power (kgeq/kWe) | D12: Thermal Control (kgeq/kWth) | E12: Cold Storage (kgeq/kg) | F12: Waste Storage (kgeq/kg) | G12: Water Treatment (kgeq/kg) | H12: Crew Time (kgeq/CM-h)
A13: Mars Surface Shielded Volume ESM EQ Factors | B13: 79.3 | C13: 162 | D13: 96 | E13: 0.21 | F13: 0.93 | G13: 0.3 | H13: 0.94
A15: PTH-Fc Expression Level by Scenario
A16: Scenario | B16: Host | C16: Expression Level (mg PTH-Fc dimer/kg FW) | D16: Days to Harvest | E16: Concurrent Batches for weekly Batches
A17: TRANSGENIC-LETTUCE | B17: L. sativa | C17: 7.1 | D17: 28 | E17: =+D17/7 -> 4
A18: TRANSGENIC-TOBACCO | B18: N. benthamiana | C18: 28.6 | D18: 35 | E18: =+D18/7 -> 5
A19: GENE GUN | B19: L. sativa | C19: 2.5 | D19: 28 | E19: =+D19/7 -> 4
A20: AGRO | B20: N. benthamiana | C20: 373 | D20: 35 | E20: =+D20/7 -> 5
A21: VIRAL | B21: N. benthamiana | C21: 300 | D21: 35 | E21: =+D21/7 -> 5

Sheet FLOWN
A1: FLOWN
A3: Key Assumptions
A4: • Each injection pen contains 0.600 mg of PTH-Fc per pen (2.4 mL with a 0.25 mg/mL concentration), the same as the mass of biologic in each Forteo injection pen
A5: • Pens must be refrigerated at 2-8°C during storage and between uses
A6: • Needles are neglected, as these might be required for all delivery routes
A7: • Shelf life at refrigerated conditions is assumed to be at least 2 years under refrigerated storage conditions based on https://www.ema.europa.eu/en/documents/scientific-discussion/forsteo-epar-scientific-discussion_en.pdf
A8: • 602 days of surface operation with 86 weekly batches
A9: • Pens are stored at 4°C in an ISS refrigerator per BVAD 2022 Table 4-49; multiple refrigerators of the same size are used as needed
A12: Calculated Quantity | B12: Value | C12: Units | D12: Notes | F12: Legend
A13: Dose required | B13: =Assumptions!B8 -> 5 | C13: mg PTH-Fc/CM/week | F13: User-editable cell
A14: Number of pens required per CM over 600 days | B14: =ROUNDUP(+$B$13*Assumptions!B7/(28*0.02),0) -> 768 | C14: unit | D14: Calculated | F14: Not applicable / No data
A15: Mass of a single box containing an injector pen | B15: 87 | C15: grams | D15: Estimate
A16: Volume of a single box containing an injector pen | B16: 30 | C16: inch3 | D16: Estimate
A17: Mass of single box without the injector pen | B17: 52 | C17: grams | D17: Estimate
A18: Mass of single Forteo injection pen (full) | B18: 35 | C18: grams | D18: Estimate
A19: Volume of a single Forteo injection pen | B19: 1.6 | C19: inch3 | D19: Estimate
A20: Mass of a single Forteo injection pen (empty) | B20: 32.76 | C20: grams | D20: Calculated
A21: Volume of a single crushed box/packaging | B21: 9 | C21: inch3 | D21: Assumed/calculated
A22: Min. refrigerator volume for 600-day supply, 1 CM | B22: =B16*B14*0.0254^3 -> 0.37755795 | C22: m3 | D22: Calculated
A24: System FOM Metrics
A25: Process Step | B25: Equipment | C25: Qty (units) | D25: Mass (kg) | E25: Volume (m3) | F25: Power (kWe) | G25: Crew Time (CM-hr)
A26: Refrigeration | B26: Refrigerator/Freezer | C26: =+ROUNDUP(B22/0.614,0) -> 1 | D26: =(321+91)*C26 -> 412 | E26: =2*C26 -> 2 | F26: =0.205*C26 -> 0.205 | G26: 0
A28: Input, Output, and Waste FOM Metrics (600-day mission)
A29: Process Step | B29: Category | C29: Qty (units) | D29: Mass (kg) | E29: Volume (m3) | F29: Crew Time (CM-hr) | G29: Power (kWe)
A30: Forteo Pen Usage | B30: Input | C30: =B14 -> 768 | D30: =(B15*B14)/1000 -> 66.816 | E30: =+C30*B16*0.000016387 -> 0.37755648 | F30: 0 | G30: 0
B31: Output | C31: 0 | D31: 0 | E31: 0 | F31: 0 | G31: 0
B32: Forteo pen waste | C32: =+B14 -> 768 | D32: =+C32*B18/1000 -> 26.88 | E32: =(B19*0.0254^3)*C32 -> 0.020136424
B33: Packaging waste | C33: =+B14 -> 768 | D33: =(B17*C33)/1000 -> 39.936 | E33: =(B21*0.0254^3)*C33 -> 0.11326739
A35: Equivalent System Mass Metrics (per CM for entire mission)
A36: Metric | B36: System | C36: Process Inputs (per CM per mission) | D36: Waste Outputs (per CM per mission) | E36: Useful Outputs (per CM per mission) | F36: Process Operations (per CM per mission)
A37: Mass (kg) | B37: =D26 -> 412 | C37: =+D30 -> 66.816 | E37: 0
A38: Volume (m3) | B38: =E26 -> 2 | C38: =E30 -> 0.37755648 | E38: 0
A39: Power (kWe) | B39: =F26 -> 0.205 | E39: 0
A40: Thermal Control (kWth) | B40: =F26 -> 0.205
A41: Cold storage mass (kg) | C41: 0 | E41: 0
A42: Crew time (hr) | B42: =G26 -> 0 | F42: 0
A43: Water mass (kg) | B43: 0 | C43: 0 | E43: 0
A44: Solid waste (kg) | D44: =SUM(D32:D33) -> 66.816
A46: 2022 Baseline Values and Assumptions
A47: Parameter | B47: Volume (kgeq/m3) | C47: Power (kgeq/kWe) | D47: Thermal Control (kgeq/kWth) | E47: Cold Storage (kgeq/kg) | F47: Waste storage (kgeq/kg) | G47: Water Treatment (kgeq/kg) | H47: Crew Time (kg/CM-h)
...

Sheet TRANSGENIC-LETTUCE
A1: TRANSGENIC-LETTUCE
A3: PTH-Fc Production Input
B4: Qty | C4: Unit | E4: Legend
A5: Therapeutic dosage (injection or oral): | B5: =Assumptions!B8 -> 5 | C5: mg PTH-Fc /wk/CM | E5: User-editable cell
A6: Avg PTH-Fc production level: | B6: =Assumptions!C17 -> 7.1 | C6: mg PTH-Fc /kg FW | E6: Not applicable / No data
A9: PLANT GROWTH METRICS
A11: Lettuce Harvest and Planting Metrics
A12: Per 1 harvest cycle and 1 CM
B13: Qty | C13: Unit
A14: Number of harvest cycles | B14: =Assumptions!E17 -> 4 | C14: harvest cycles
A15: Edible biomass at harvest | B15: =(131.35*28)/1000 -> 3.6778 | C15: kg FW/m2
A16: Lettuce planting density | B16: 19.2 | C16: plants/m2
A17: Theoretical mass plant at harvest | B17: =B15/B16 -> 0.19155208 | C17: kg FW/plant
A18: Mass plant required for therapeutic dosage | B18: =B5*(1/B6) -> 0.70422535 | C18: kg FW/wk
A19: Number of plants at harvest | B19: =ROUNDUP(B18/B17,0) -> 4 | C19: plants/wk (dose)
A20: Actual mass plant at harvest, accounting for dosage | B20: =B17*B19 -> 0.76620833 | C20: kg FW/wk
A21: Planting area | B21: =B20/B15 -> 0.20833333 | C21: m2
A22: Per 4 harvest cycles and 1 CM
B23: Qty | C23: Unit
A24: Number of plants | B24: =B19*B14 -> 16 | C24: plants
A25: Mass of plants | B25: =B17*B24 -> 3.0648333 | C25: kg FW
A26: Planting area | B26: =B25/B15 -> 0.83333333 | C26: m2
A28: System FOM Metrics
A29: Process Step | B29: Equipment | C29: Qty (units) | D29: Mass (kg) | E29: Volume (m3) | F29: Power (kWe) | G29: Crew Time (CM-h)
A30: 1: Plant Growth Infrastructure | B30: Plant growth chamber | C30: 1 | D30: =(101.5-22.9-8.4)*B26 -> 58.5 | E30: =(1.03-0.25)*B26 -> 0.65 | F30: =(2.6-2.1-0.075)*B26 -> 0.35416667
B31: Lighting panels | C31: =ROUNDUP(B26*9,0) -> 8 | D31: =0.243*C31 -> 1.944 | E31: =(0.3*0.3*0.001)*C31 -> 0.00072 | F31: =50.7*C31*(1/1000) -> 0.4056
A32: 2: Leaf Harvest Infrastructure | B32: Refrigerator/Freezer | C32: =IF((0.003785*C34*2) <= 0.0187, 1, CEILING((0.003785*C34*2)/0.0187, 1)) -> 2 | D32: =0.75*B20*C32 -> 1.1493125 | E32: =0.00393*B20*C32 -> 0.0060223975 | F32: =0.00033*B20*C32 -> 0.0005056975
B33: Harvesting tools (scissors) | C33: =IF(F46 <= 2, 1, CEILING(F46 / 2, 1)) -> 1 | D33: =0.20411*C33/Assumptions!$B$5 -> 0.034018333 | E33: =0.00064416*C33/Assumptions!$B$5 -> 0.00010736 | H33: Shared across crew, divided by crew size (Assumptions!B5)
B34: Harvest collection container (bags) | C34: =ROUNDUP(B20/(85*0.003785),0) -> 3 | D34: =(7.62/250)*(0.45359/1)*C34 -> 0.04147627 | E34: =(10.5*11*0.00394)*0.00001639*C34 -> 2.2375792e-05
A36: Input, Output, Waste FOM Metrics (1 cycle, 28-day batch time)
A37: Process Step | B37: Input | C37: Mass (kg) | D37: Volume (m3) | E37: Power (kWe) | F37: Crew Time (CM-h)
A38: 1: Plant Growth | B38: Lettuce seeds | C38: =B19*(1.01/1000000) -> 4.04e-06 | D38: =((4.57*1.524*0.5)/(1000^3))*B19 -> 1.392936e-08 | F38: =B19*(1/10)*(1/60)*1.5 -> 0.01
B39: Water | C39: =D39*1000 -> 14.478333 | D39: =(7.3*B21*28)*0.34*0.001 -> 0.014478333 | F39: =90*4*(1/60)*(1/12.5)*(1/365)*28*B21*1.5 -> 0.011506849
B40: Plant nutrients | C40: =(1.166+(12.406*3))*(1/1000)*D39*1000 -> 0.55573635 | F40: =(20.17/10)*(1/60)*(1/12.5)*B21*28*1.5 -> 0.023531667
B41: Carbon dioxide | C41: =(10.7*B21*28)/1000 -> 0.062416667 | D41: =C41/1.82 -> 0.034294872 | F41: =2.13*365*(1/60)*(1/365)*28*1.5 -> 1.491
B42: Output | C42: Mass (kg) | D42: Volume (m3) | E42: Power (kWe) | F42: Crew Time (CM-h)
B43: Oxygen | C43: =7.78*B21*28*(1/1000) -> 0.045383333 | D43: =C43*(1/1.3) -> 0.034910256
B44: Water (transpiration) | C44: =2.1*B21*28 -> 12.25 | D44: =C44*(1/1000) -> 0.01225
A45: Process Step | B45: Output | C45: Mass (kg) | D45: Volume (m3) | E45: Power (kWe) | F45: Crew Time (CM-h)
A46: 2: Leaf Harvest | B46: PTH-Fc | C46: =B5*(1/1000000) -> 5e-06 | F46: =(3.97*B21)*(1/60)*1.5 -> 0.020677083
...

Sheet TRANSGENIC-TOBACCO
A1: TRANSGENIC-TOBACCO
A3: PTH-Fc Production Input
B4: Qty | C4: Unit | E4: Legend
A5: Therapeutic dosage (injection or oral): | B5: =Assumptions!B8 -> 5 | C5: mg PTH-Fc/wk/CM | E5: User-editable cell
A6: Avg PTH-Fc production level: | B6: =Assumptions!C18 -> 28.6 | C6: mg PTH-Fc/kg FW | E6: Not applicable / No data
A9: PLANT GROWTH METRICS
A11: Tobacco Harvest and Planting Metrics
A12: Per 1 harvest cycle and 1 CM
B13: Qty | C13: Unit
A14: Number of harvest cycles | B14: =Assumptions!E18 -> 5 | C14: harvest cycles
A15: Biomass at harvest | B15: =(320/16)*(1/0.0929)*(9830000/982000)*(1/1000) -> 2.1550448 | C15: kg FW/m2
A16: Theoretical mass plant at harvest | B16: =(9830000/982000)*(1/1000) -> 0.010010183 | C16: kg FW/plant
A17: Mass plant required for therapeutic dosage | B17: =B5*(1/B6) -> 0.17482517 | C17: kg FW/wk
A18: Number of plants at harvest | B18: =ROUNDUP(B17/B16,0) -> 18 | C18: plants/wk (dose)
A19: Planting area | B19: =B17/B15 -> 0.081123683 | C19: m2
A20: Per 5 harvest cycles and 1 CM
B21: Qty | C21: Unit
A22: Number of plants | B22: =B18*B14 -> 90 | C22: plants
A23: Mass of plants | B23: =B16*B22 -> 0.9009165 | C23: kg FW
A24: Planting area | B24: =B23/B15 -> 0.41805 | C24: m2
A26: System FOM Metrics
A27: Process Step | B27: Equipment | C27: Qty (units) | D27: Mass (kg) | E27: Volume (m3) | F27: Power (kWe) | G27: Crew Time (CM-h)
A28: 1: Plant Growth | B28: Plant growth chamber | C28: 1 | D28: =(101.5-22.9-8.4)*B24 -> 29.34711 | E28: =(1.03-0.25)*B24 -> 0.326079 | F28: =(2.6-2.1-0.075)*B24 -> 0.17767125
B29: Lighting panels | C29: =ROUNDUP(B24*9,0) -> 4 | D29: =0.243*C29 -> 0.972 | E29: =(0.3*0.3*0.001)*C29 -> 0.00036 | F29: =50.7*C29*(1/1000) -> 0.2028
A30: 2: Leaf Harvest | B30: Refrigerator/Freezer | C30: =IF((0.003785*C32*2) <= 0.0187, 1, CEILING((0.003785*C32*2)/0.0187, 1)) -> 1 | D30: =0.75*B17*C30 -> 0.13111888 | E30: =0.00393*B17*C30 -> 0.00068706294 | F30: =0.00033*B17*C30 -> 5.7692308e-05
B31: Harvesting tools (scissors) | C31: =IF(F44 <= 2, 1, CEILING(F44 / 2, 1)) -> 1 | D31: =0.20411*C31/Assumptions!$B$5 -> 0.034018333 | E31: =0.00064416*C31/Assumptions!$B$5 -> 0.00010736 | H31: Shared across crew, divided by crew size (Assumptions!B5)
B32: Harvest collection container (bags) | C32: =ROUNDUP(B17/(85*0.003785),0) -> 1 | D32: =(7.62/250)*(0.45359/1)*C32 -> 0.013825423 | E32: =(10.5*11*0.00394)*0.00001639*C32 -> 7.4585973e-06
A34: Input, Output, Waste FOM Metrics (1 cycle, 35-day batch time)
A35: Process Step | B35: Input | C35: Mass (kg) | D35: Volume (m3) | E35: Power (kWe) | F35: Crew Time (CM-h)
A36: 1: Plant Growth | B36: N. benthamiana seeds | C36: =0.0004288*B18*2 -> 0.0154368 | D36: =(4/3)*PI()*((0.45/2)^3)*(1/1000^3) -> 4.7712938e-11 | F36: =((B18*2)*(1/10)*(1/60)*1.5)+(4.6*(1/(215*2))*1.5) -> 0.10604651
B37: Water | C37: =D37*1000 -> 7.0472143 | D37: =(7.3*B19*35)*0.34*0.001 -> 0.0070472143 | F37: =90*4*(1/60)*(1/12.5)*(1/365)*35*B19*1.5 -> 0.005600868
B38: Plant nutrients | C38: =((1.166+(12.406*3))*(D37*1000))/1000 -> 0.27050028 | F38: =(20.17/10)*(1/60)*(1/12.5)*B19*35*1.5 -> 0.011453853
B39: Carbon dioxide | C39: =(10.7*B19*35)/1000 -> 0.030380819 | D39: =C39/1.82 -> 0.016692758 | F39: =2.13*365*(1/60)*(1/365)*35*1.5 -> 1.86375
B40: Output | C40: Mass (kg) | D40: Volume (m3) | E40: Power (kWe) | F40: Crew Time (CM-h)
B41: Oxygen | C41: =(7.78*B19*35)/1000 -> 0.022089979 | D41: =C41/1.3 -> 0.016992291
B42: Water (transpiration) | C42: =2.1*B19*35 -> 5.9625907 | D42: =C42/1000 -> 0.0059625907
A43: Process Step | B43: Output | C43: Mass (kg) | D43: Volume (m3) | E43: Power (kWe) | F43: Crew Time (CM-h)
A44: 2: Leaf Harvest | B44: PTH-Fc | C44: =B5/1000000 -> 5e-06 | F44: =(3.97*B19)*(1/60)*1.5 -> 0.0080515255
B45: Plant biomass | C45: =B15*B19 -> 0.17482517 | D45: =C45*(1/60) -> 0.0029137529
B46: Waste | C46: Mass (kg) | D46: Volume (m3) | E46: Power (kWe) | F46: Crew Time (CM-h)
...

Sheet GENE GUN
A1: GENE GUN
A3: PTH-Fc Production Input
B4: Qty | C4: Unit | E4: Legend
A5: Therapeutic dosage (injection or oral): | B5: =Assumptions!B8 -> 5 | C5: mg PTH-Fc/wk/CM | E5: User-editable cell
A6: Avg PTH-Fc production level: | B6: =Assumptions!C19 -> 2.5 | C6: mg PTH-Fc/kg FW | E6: Not applicable / No data
A9: PLANT GROWTH METRICS
A11: Lettuce Harvest and Planting Metrics
A12: Per 1 harvest cycle and 1 CM
B13: Qty | C13: Unit
A14: Number of harvest cycles | B14: 4 | C14: harvest cycles
A15: Edible biomass at harvest | B15: =(131.35*28)/1000 -> 3.6778 | C15: kg FW/m2
A16: Lettuce planting density | B16: 19.2 | C16: plants/m2
A17: Theoretical mass plant at harvest | B17: =B15/B16 -> 0.19155208 | C17: kg FW/plant
A18: Mass plant required for therapeutic dosage | B18: =B5*(1/B6) -> 2 | C18: kg FW/wk
A19: Number of plants at harvest | B19: =ROUNDUP(B18/B17,0) -> 11 | C19: plants/wk (dose)
A20: Actual mass plant at harvest, accounting for dosage | B20: =B17*B19 -> 2.1070729 | C20: kg FW/wk
A21: Planting area | B21: =B20/B15 -> 0.57291667 | C21: m2
A22: Per 4 harvest cycles and 1 CM
B23: Qty | C23: Unit
A24: Number of plants | B24: =B19*B14 -> 44 | C24: plants
A25: Mass of plants | B25: =B17*B24 -> 8.4282917 | C25: kg FW
A26: Planting area | B26: =B25/B15 -> 2.2916667 | C26: m2
A28: System FOM Metrics
A29: Process Step | B29: Equipment | C29: Qty (units) | D29: Mass (kg) | E29: Volume (m3) | F29: Power (kWe) | G29: Crew Time (CM-h)
A30: 1: Plant Growth | B30: Plant growth chamber | C30: 1 | D30: =(101.5-22.9-8.4)*B26 -> 160.875 | E30: =(1.03-0.25)*B26 -> 1.7875 | F30: =(2.6-2.1-0.075)*B26 -> 0.97395833
B31: Lighting panels | C31: =ROUNDUP(B26*9,0) -> 21 | D31: =0.243*C31 -> 5.103 | E31: =(0.3*0.3*0.001)*C31 -> 0.00189 | F31: =50.7*C31*(1/1000) -> 1.0647
A32: 2: Leaf Harvest | B32: Refrigerator/Freezer | C32: =IF((0.003785*C34*2) <= 0.0187, 1, CEILING((0.003785*C34*2)/0.0187, 1)) -> 3 | D32: =0.75*B20*C32 -> 4.7409141 | E32: =0.00393*B20*C32 -> 0.02484239 | F32: =0.00033*B20*C32 -> 0.0020860022
B33: Harvesting tools (scissors) | C33: =IF(F46 <= 2, 1, CEILING(F46 / 2, 1)) -> 1 | D33: =0.20411*C33/Assumptions!$B$5 -> 0.034018333 | E33: =0.00064416*C33/Assumptions!$B$5 -> 0.00010736 | H33: Shared across crew, divided by crew size (Assumptions!B5)
B34: Harvest collection container (bags) | C34: =ROUNDUP(B20/(85*0.003785),0) -> 7 | D34: =(7.62/250)*(0.45359/1)*C34 -> 0.096777962 | E34: =(10.5*11*0.00394)*0.00001639*C34 -> 5.2210181e-05
A36: Input, Output, Waste FOM Metrics (1 cycle, 28-day batch time)
A37: Process Step | B37: Input | C37: Mass (kg) | D37: Volume (m3) | E37: Power (kWe) | F37: Crew Time (CM-h)
A38: 1: Plant Growth | B38: Lettuce seeds | C38: =B19*(1.01/1000000) -> 1.111e-05 | D38: =((4.57*1.524*0.5)/(1000^3))*B19 -> 3.830574e-08 | F38: =B19/(10*60)*1.5 -> 0.0275
B39: Water | C39: =D39*1000 -> 39.815417 | D39: =(7.3*B21*28)*0.34*0.001 -> 0.039815417 | F39: =90*4*(1/60)*(1/12.5)*(1/365)*28*B21*1.5 -> 0.031643836
B40: Plant nutrients | C40: =(1.166+(12.406*3))*(1/1000)*D39*1000 -> 1.528275 | F40: =(20.17/10)*(1/60)*(1/12.5)*B21*28*1.5 -> 0.064712083
B41: Carbon dioxide | C41: =(10.7*B21*28)/1000 -> 0.17164583 | D41: =C41/1.82 -> 0.094310897 | F41: =2.13*365*(1/60)*(1/365)*28*1.5 -> 1.491
B42: Output | C42: Mass (kg) | D42: Volume (m3) | E42: Power (kWe) | F42: Crew Time (CM-h)
B43: Oxygen | C43: =7.78*B21*28*(1/1000) -> 0.12480417 | D43: =C43*(1/1.3) -> 0.096003205
B44: Water (transpiration) | C44: =2.1*B21*28 -> 33.6875 | D44: =C44*(1/1000) -> 0.0336875
A45: Process Step | B45: Output | C45: Mass (kg) | D45: Volume (m3) | E45: Power (kWe) | F45: Crew Time (CM-h)
A46: 2: Leaf Harvest | B46: PTH-Fc | C46: =B5*(1/1000000) -> 5e-06 | F46: =(3.97*B21)*(1/60)*1.5 -> 0.056861979
...

Sheet AGRO
A1: AGRO
A3: PTH-Fc Production Input
B4: Qty | C4: Unit | E4: Legend
A5: Therapeutic dosage (injection or oral): | B5: =Assumptions!B8 -> 5 | C5: mg PTH-Fc/wk/CM | E5: User-editable cell
A6: Avg PTH-Fc production level: | B6: =Assumptions!C20 -> 373 | C6: mg PTH-Fc/kg FW | E6: Not applicable / No data
A9: PLANT GROWTH METRICS
A11: Tobacco Harvest and Planting Metrics
A12: Per 1 harvest cycle and 1 CM
B13: Qty | C13: Unit
A14: Number of harvest cycles | B14: 5 | C14: harvest cycles
A15: Biomass at harvest | B15: =(320/16)*(1/0.0929)*(9830000/982000)*(1/1000) -> 2.1550448 | C15: kg FW/m2
A16: Theoretical mass plant at harvest | B16: =(9830000/982000)*(1/1000) -> 0.010010183 | C16: kg FW/plant
A17: Mass plant required for therapeutic dosage | B17: =B5*(1/B6) -> 0.013404826 | C17: kg FW/wk
A18: Number of plants at harvest | B18: =ROUNDUP(B17/B16,0) -> 2 | C18: plants/wk (dose)
A19: Planting area | B19: =B17/B15 -> 0.0062202073 | C19: m2
A20: Per 5 harvest cycles and 1 CM
B21: Qty | C21: Unit
A22: Number of plants | B22: =B18*B14 -> 10 | C22: plants
A23: Mass of plants | B23: =B16*B22 -> 0.10010183 | C23: kg FW
A24: Planting area | B24: =B23/B15 -> 0.04645 | C24: m2
A26: System FOM Metrics
A27: Process Step | B27: Equipment | C27: Qty (units) | D27: Mass (kg) | E27: Volume (m3) | F27: Power (kWe) | G27: Crew Time (CM-h)
A28: 1: Plant Growth | B28: Plant growth chamber | C28: 1 | D28: =(101.5-22.9-8.4)*B24 -> 3.26079 | E28: =(1.03-0.25)*B24 -> 0.036231 | F28: =(2.6-2.1-0.075)*B24 -> 0.01974125
B29: Lighting panels | C29: =ROUNDUP(B24*9,0) -> 1 | D29: =0.243*C29 -> 0.243 | E29: =(0.3*0.3*0.001)*C29 -> 9e-05 | F29: =50.7*C29*(1/1000) -> 0.0507
A30: 2: Leaf Harvest | B30: Refrigerator/Freezer | C30: =IF((0.003785*C32*2) <= 0.0187, 1, CEILING((0.003785*C32*2)/0.0187, 1)) -> 1 | D30: =0.75*B17*C30 -> 0.010053619 | E30: =0.00393*B17*C30 -> 5.2680965e-05 | F30: =0.00033*B17*C30 -> 4.4235925e-06
B31: Harvesting tools (scissors) | C31: =IF(F44 <= 2, 1, CEILING(F44 / 2, 1)) -> 1 | D31: =0.20411*C31/Assumptions!$B$5 -> 0.034018333 | E31: =0.00064416*C31/Assumptions!$B$5 -> 0.00010736 | H31: Shared across crew, divided by crew size (Assumptions!B5)
B32: Harvest collection container (bags) | C32: =ROUNDUP(B17/(85*0.003785),0) -> 1 | D32: =(7.62/250)*(0.45359/1)*C32 -> 0.013825423 | E32: =(10.5*11*0.00394)*0.00001639*C32 -> 7.4585973e-06
A34: Input, Output, Waste FOM Metrics (1 cycle, 35-day batch time)
A35: Process Step | B35: Input | C35: Mass (kg) | D35: Volume (m3) | E35: Power (kWe) | F35: Crew Time (CM-h)
A36: 1: Plant Growth | B36: N. benth seeds | C36: =0.0004288*B18*2 -> 0.0017152 | D36: =(4/3)*PI()*((0.45/2)^3)*(1/1000^3) -> 4.7712938e-11 | F36: =((1/10)*(B18*2)*(1/60)*1.5)+(4.6*(1/(215*2))*1.5) -> 0.026046512
B37: Water | C37: =D37*1000 -> 0.54034941 | D37: =(7.3*B19*35)*0.34*0.001 -> 0.00054034941 | F37: =90*4*(1/60)*(1/12.5)*(1/365)*35*B19*1.5 -> 0.00042944993
B38: Plant nutrients | C38: =((1.166+(12.406*3))*(D37*1000))/1000 -> 0.020740772 | F38: =(20.17/10)*(1/60)*(1/12.5)*B19*35*1.5 -> 0.00087823107
B39: Carbon dioxide | C39: =(10.7*B19*35)/1000 -> 0.0023294676 | D39: =C39/1.82 -> 0.0012799273 | F39: =2.13*365*(1/60)*(1/365)*35*1.5 -> 1.86375
B40: Output | C40: Mass (kg) | D40: Volume (m3) | E40: Power (kWe) | F40: Crew Time (CM-h)
B41: Oxygen | C41: =(7.78*B19*35)/1000 -> 0.0016937625 | D41: =C41/1.3 -> 0.0013028942
B42: Water (transpiration) | C42: =2.1*B19*35 -> 0.45718524 | D42: =C42/1000 -> 0.00045718524
A43: Process Step | B43: Output | C43: Mass (kg) | D43: Volume (m3) | E43: Power (kWe) | F43: Crew Time (CM-h)
A44: 2: Leaf Harvest | B44: PTH-Fc | C44: =B5/1000000 -> 5e-06 | F44: =(3.97*B19)/60*1.5 -> 0.00061735558
B45: Plant biomass | C45: =B15*B19 -> 0.013404826 | D45: =C45*(1/60) -> 0.00022341376
B46: Waste | C46: Mass (kg) | D46: Volume (m3) | E46: Power (kWe) | F46: Crew Time (CM-h)
...

Sheet VIRAL
A1: VIRAL
A3: PTH-Fc Production Input
B4: =Assumptions!B8 -> 5 | C4: Unit | E4: Legend
A5: Therapeutic dosage (injection or oral): | B5: =Assumptions!B8 -> 5 | C5: mg PTH-Fc/wk/CM | E5: User-editable cell
A6: Avg PTH-Fc production level: | B6: =Assumptions!C21 -> 300 | C6: mg PTH-Fc/kg FW | E6: Not applicable / No data
A9: PLANT GROWTH METRICS
A11: Tobacco Harvest and Planting Metrics
A12: Per 1 harvest cycle and 1 CM
B13: Qty | C13: Unit
A14: Number of harvest cycles | B14: 5 | C14: harvest cycles
A15: Biomass at harvest | B15: =(320/16)*(1/0.0929)*(9830000/982000)*(1/1000) -> 2.1550448 | C15: kg FW/m2
A16: Theoretical mass plant at harvest | B16: =(9830000/982000)*(1/1000) -> 0.010010183 | C16: kg FW/plant
A17: Mass plant required for therapeutic dosage | B17: =B5*(1/B6) -> 0.016666667 | C17: kg FW/wk
A18: Number of plants at harvest | B18: =ROUNDUP(B17/B16,0) -> 2 | C18: plants/wk (dose)
A19: Planting area | B19: =B17/B15 -> 0.0077337911 | C19: m2
A20: Per 5 harvest cycles and 1 CM
B21: Qty | C21: Unit
A22: Number of plants | B22: =B18*B14 -> 10 | C22: plants
A23: Mass of plants | B23: =B16*B22 -> 0.10010183 | C23: kg FW
A24: Planting area | B24: =B23/B15 -> 0.04645 | C24: m2
A26: System FOM Metrics
A27: Process Step | B27: Equipment | C27: Qty (units) | D27: Mass (kg) | E27: Volume (m3) | F27: Power (kWe) | G27: Crew Time (CM-h)
A28: 1: Plant Growth | B28: Plant growth chamber | C28: 1 | D28: =(101.5-22.9-8.4)*B24 -> 3.26079 | E28: =(1.03-0.25)*B24 -> 0.036231 | F28: =(2.6-2.1-0.075)*B24 -> 0.01974125
B29: Lighting panels | C29: =ROUNDUP(B24*9,0) -> 1 | D29: =0.243*C29 -> 0.243 | E29: =(0.3*0.3*0.001)*C29 -> 9e-05 | F29: =50.7*C29*(1/1000) -> 0.0507
A30: 2: Leaf Harvest | B30: Refrigerator/Freezer | C30: =IF((0.003785*C32*2) <= 0.0187, 1, CEILING((0.003785*C32*2)/0.0187, 1)) -> 1 | D30: =0.75*B17*C30 -> 0.0125 | E30: =0.00393*B17*C30 -> 6.55e-05 | F30: =0.00033*B17*C30 -> 5.5e-06
B31: Harvesting tools (scissors) | C31: =IF(F44 <= 2, 1, CEILING(F44 / 2, 1)) -> 1 | D31: =0.20411*C31/Assumptions!$B$5 -> 0.034018333 | E31: =0.00064416*C31/Assumptions!$B$5 -> 0.00010736 | H31: Shared across crew, divided by crew size (Assumptions!B5)
B32: Harvest collection container (bags) | C32: =ROUNDUP(B17/(85*0.003785),0) -> 1 | D32: =(7.62/250)*(0.45359/1)*C32 -> 0.013825423 | E32: =(10.5*11*0.00394)*0.00001639*C32 -> 7.4585973e-06
A34: Input, Output, Waste FOM Metrics (1 cycle, 28-day batch time)
A35: Process Step | B35: Input | C35: Mass (kg) | D35: Volume (m3) | E35: Power (kWe) | F35: Crew Time (CM-h)
A36: 1: Plant Growth | B36: N. benth seeds | C36: =0.0004288*B18*2 -> 0.0017152 | D36: =(4/3)*PI()*((0.45/2)^3)*(1/1000^3) -> 4.7712938e-11 | F36: =((1/10)*(B18*2)*(1/60)*1.5)+(4.6*(1/(215*2))*1.5) -> 0.026046512
B37: Water | C37: =D37*1000 -> 0.67183443 | D37: =(7.3*B19*35)*0.34*0.001 -> 0.00067183443 | F37: =90*4*(1/60)*(1/12.5)*(1/365)*35*B19*1.5 -> 0.00053394941
B38: Plant nutrients | C38: =((1.166+(12.406*3))*(D37*1000))/1000 -> 0.025787693 | F38: =(20.17/10)*(1/60)*(1/12.5)*B19*35*1.5 -> 0.001091934
B39: Carbon dioxide | C39: =(10.7*B19*35)/1000 -> 0.0028963048 | D39: =C39/1.82 -> 0.0015913762 | F39: =2.13*365*(1/60)*(1/365)*35*1.5 -> 1.86375
B40: Output | C40: Mass (kg) | D40: Volume (m3) | E40: Power (kWe) | F40: Crew Time (CM-h)
B41: Oxygen | C41: =(7.78*B19*35)/1000 -> 0.0021059113 | D41: =C41/1.3 -> 0.0016199318
B42: Water (transpiration) | C42: =2.1*B19*35 -> 0.56843365 | D42: =C42/1000 -> 0.00056843365
A43: Process Step | B43: Output | C43: Mass (kg) | D43: Volume (m3) | E43: Power (kWe) | F43: Crew Time (CM-h)
A44: 2: Leaf Harvest | B44: PTH-Fc | C44: =B5/1000000 -> 5e-06 | F44: =(3.97*B19)/60*1.5 -> 0.00076757877
B45: Plant biomass | C45: =B15*B19 -> 0.016666667 | D45: =C45*(1/60) -> 0.00027777778
B46: Waste | C46: Mass (kg) | D46: Volume (m3) | E46: Power (kWe) | F46: Crew Time (CM-h)
...
