Workbook

Sheet Assumptions
A1: Shared Assumptions and Equivalency Factors
A3: Mission Parameters
A4: Parameter | B4: Value | C4: Unit | E4: Legend
A5: Crew size | B5: 6 | C5: crew members | E5: User-editable cell
A6: Mission surface duration | B6: =+B7*7 -> 602 | C6: days | E6: Not applicable / No data
A7: Mission duration (weeks) | B7: 86 | C7: weeks
A8: Base case dose | B8: 5 | C8: mg PTH-Fc/CM/week
A9: Total mission dose per CM | B9: =B7*B8 -> 430 | C9: mg PTH-Fc/CM/mission
A11: 2022 Baseline Values and Assumptions
A12: Parameter | B12: Volume (kgeq/m3) | C12: Power (kgeq/kWe) | D12: Thermal Control (kgeq/kWth) | E12: Cold Storage (kgeq/kg) | F12: Waste Storage (kgeq/kg) | G12: Water Treatment (kgeq/kg) | H12: Crew Time (kgeq/CM-h)
A13: Mars Surface Shielded Volume ESM EQ Factors | B13: 79.3 | C13: 162 | D13: 96 | E13: 0.21 | F13: 0.93 | G13: 0.3 | H13: 0.94
A15: PTH-Fc Expression Level by Scenario
A16: Scenario | B16: Host | C16: Expression Level (mg PTH-Fc dimer/kg FW) | D16: Days to Harvest | E16: Concurrent Batches for weekly Batches
A17: TRANSGENIC-LETTUCE | B17: L. sativa | C17: 7.1 | D17: 28 | E17: =+D17/7 -> 4
A18: TRANSGENIC-TOBACCO | B18: N. benthamiana | C18: 28.6 | D18: 35 | E18: =+D18/7 -> 5
A19: GENE GUN | B19: L. sativa | C19: 2.5 | D19: 28 | E19: =+D19/7 -> 4
A20: AGRO | B20: N. benthamiana | C20: 373 | D20: 35 | E20: =+D20/7 -> 5
A21: VIRAL | B21: N. benthamiana | C21: 300 | D21: 35 | E21: =+D21/7 -> 5

Sheet FLOWN
A1: FLOWN
A3: Key Assumptions
A4: • Each injection pen contains 0.600 mg of PTH-Fc per pen (2.4 mL with a 0.25 mg/mL concentration), the same as the mass of biologic in each Forteo injection pen
A5: • Pens must be refrigerated at 2-8°C during storage and between uses
A6: • Needles are neglected, as these might be required for all delivery routes
A7: • Shelf life at refrigerated conditions is assumed to be at least 2 years under refrigerated storage conditions based on https://www.ema.europa.eu/en/documents/scientific-discussion/forsteo-epar-scientific-discussion_en.pdf
A8: • 602 days of surface operation with 86 weekly batches
A9: • Pens are stored at 4°C in an ISS refrigerator per BVAD 2022 Table 4-49; multiple refrigerators of the same size are used as needed
A12: Calculated Quantity | B12: Value | C12: Units | D12: Notes | F12: Legend
A13: Dose required | B13: =Assumptions!B8 -> 5 | C13: mg PTH-Fc/CM/week | F13: User-editable cell
A14: Number of pens required per CM over 600 days | B14: =ROUNDUP(+$B$13*ROUNDUP(600/7,0)/(28*0.02),0) -> 768 | C14: unit | D14: Calculated | F14: Not applicable / No data
A15: Mass of a single box containing an injector pen | B15: 87 | C15: grams | D15: Estimate
A16: Volume of a single box containing an injector pen | B16: 30 | C16: inch3 | D16: Estimate
A17: Mass of single box without the injector pen | B17: 52 | C17: grams | D17: Estimate
A18: Mass of single Forteo injection pen (full) | B18: 35 | C18: grams | D18: Estimate
A19: Volume of a single Forteo injection pen | B19: 1.6 | C19: inch3 | D19: Estimate
A20: Mass of a single Forteo injection pen (empty) | B20: 32.76 | C20: grams | D20: Calculated
A21: Volume of a single crushed box/packaging | B21: 9 | C21: inch3 | D21: Assumed/calculated
A22: Min. refrigerator volume for 600-day supply, 1 CM | B22: =B16*B14*0.0254^3 -> 0.37755795 | C22: m3 | D22: Calculated
A24: System FOM Metrics
A25: Process Step | B25: Equipment | C25: Qty (units) | D25: Mass (kg) | E25: Volume (m3) | F25: Power (kWe) | G25: Crew Time (CM-hr)
A26: Refrigeration | B26: Refrigerator/Freezer | C26: =+ROUNDUP(B22/0.614,0) -> 1 | D26: =(321+91)*C26 -> 412 | E26: =2*C26 -> 2 | F26: =0.205*C26 -> 0.205 | G26: 0
A28: Input, Output, and Waste FOM Metrics (600-day mission)
A29: Process Step | B29: Category | C29: Qty (units) | D29: Mass (kg) | E29: Volume (m3) | F29: Crew Time (CM-hr) | G29: Power (kWe)
A30: Forteo Pen Usage | B30: Input | C30: =B14 -> 768 | D30: =(B15*B14)/1000 -> 66.816 | E30: =+C30*B16*0.000016387 -> 0.37755648 | F30: 0 | G30: 0
B31: Output | C31: 0 | D31: 0 | E31: 0 | F31: 0 | G31: 0
B32: Forteo pen waste | C32: =+B14 -> 768 | D32: =+C32*B18/1000 -> 26.88 | E32: =(B19*0.0254^3)*C32 -> 0.020136424
B33: Packaging waste | C33: =+B14 -> 768 | D33: =(B17*C33)/1000 -> 39.936 | E33: =(B21*0.0254^3)*C33 -> 0.11326739
A35: Equivalent System Mass Metrics (per CM for entire mission)
A36: Metric | B36: System | C36: Process Inputs (per CM per mission) | D36: Waste Outputs (per CM per mission) | E36: Useful Outputs (per CM per mission) | F36: Process Operations (per CM per mission)
A37: Mass (kg) | B37: =D26 -> 412 | C37: =+D30 -> 66.816 | E37: 0
A38: Volume (m3) | B38: =E26 -> 2 | C38: =E30 -> 0.37755648 | E38: 0
A39: Power (kWe) | B39: =F26 -> 0.205 | E39: 0
A40: Thermal Control (kWth) | B40: =F26 -> 0.205
A41: Cold storage mass (kg) | C41: 0 | E41: 0
A42: Crew time (hr) | B42: =G26 -> 0 | F42: 0
A43: Water mass (kg) | B43: 0 | C43: 0 | E43: 0
A44: Solid waste (kg) | D44: =SUM(D32:D33) -> 66.816
A46: 2022 Baseline Values and Assumptions
A47: Parameter | B47: Volume (kgeq/m3) | C47: Power (kgeq/kWe) | D47: Thermal Control (kgeq/kWth) | E47: Cold Storage (kgeq/kg) | F47: Waste storage (kgeq/kg) | G47: Water Treatment (kgeq/kg) | H47: Crew Time (kg/CM-h)
...

Sheet TRANSGENIC-LETTUCE
A1: TRANSGENIC-LETTUCE
A3: PTH-Fc Production Input
B4: Qty | C4: Unit | E4: Legend
A5: Therapeutic dosage (injection or oral): | B5: =Assumptions!B8 -> 5 | C5: mg PTH-Fc /wk/CM | E5: User-editable cell
A6: Therapeutic dosage (injection or oral): | B6: =B5 -> 5 | C6: mg PTH-Fc/wk/CM | E6: Not applicable / No data
A7: Avg PTH-Fc production level: | B7: =Assumptions!C17 -> 7.1 | C7: mg PTH-Fc /kg FW
A10: PLANT GROWTH METRICS
A12: Lettuce Harvest and Planting Metrics
A13: Per 1 harvest cycle and 1 CM
B14: Qty | C14: Unit
A15: Number of harvest cycles | B15: =Assumptions!E17 -> 4 | C15: harvest cycles
A16: Edible biomass at harvest | B16: =(131.35*28)/1000 -> 3.6778 | C16: kg FW/m2
A17: Lettuce planting density | B17: 19.2 | C17: plants/m2
A18: Theoretical mass plant at harvest | B18: =B16/B17 -> 0.19155208 | C18: kg FW/plant
A19: Mass plant required for therapeutic dosage | B19: =B6*(1/B7) -> 0.70422535 | C19: kg FW/wk
A20: Number of plants at harvest | B20: =ROUNDUP(B19/B18,0) -> 4 | C20: plants/wk (dose)
A21: Actual mass plant at harvest, accounting for dosage | B21: =B18*B20 -> 0.76620833 | C21: kg FW/wk
A22: Planting area | B22: =B21/B16 -> 0.20833333 | C22: m2
A23: Per 4 harvest cycles and 1 CM
B24: Qty | C24: Unit
A25: Number of plants | B25: =B20*B15 -> 16 | C25: plants
A26: Mass of plants | B26: =B18*B25 -> 3.0648333 | C26: kg FW
A27: Planting area | B27: =B26/B16 -> 0.83333333 | C27: m2
A29: System FOM Metrics
A30: Process Step | B30: Equipment | C30: Qty (units) | D30: Mass (kg) | E30: Volume (m3) | F30: Power (kWe) | G30: Crew Time (CM-h)
A31: 1: Plant Growth Infrastructure | B31: Plant growth chamber | C31: 1 | D31: =(101.5-22.9-8.4)*B27 -> 58.5 | E31: =(1.03-0.25)*B27 -> 0.65 | F31: =(2.6-2.1-0.075)*B27 -> 0.35416667
B32: Lighting panels | C32: =ROUNDUP(B27*9,0) -> 8 | D32: =0.243*C32 -> 1.944 | E32: =(0.3*0.3*0.001)*C32 -> 0.00072 | F32: =50.7*C32*(1/1000) -> 0.4056
A33: 2: Leaf Harvest Infrastructure | B33: Refrigerator/Freezer | C33: =IF((0.003785*C35*2) <= 0.0187, 1, CEILING((0.003785*C35*2)/0.0187, 1)) -> 2 | D33: =0.75*B21*C33 -> 1.1493125 | E33: =0.00393*B21*C33 -> 0.0060223975 | F33: =0.00033*B21*C33 -> 0.0005056975
B34: Harvesting tools (scissors) | C34: =IF(F47 <= 2, 1, CEILING(F47 / 2, 1)) -> 1 | D34: =0.20411*C34/Assumptions!$B$5 -> 0.034018333 | E34: =0.00064416*C34/Assumptions!$B$5 -> 0.00010736 | H34: Shared across crew, divided by crew size (Assumptions!B5)
B35: Harvest collection container (bags) | C35: =ROUNDUP(B21/(85*0.003785),0) -> 3 | D35: =(7.62/250)*(0.45359/1)*C35 -> 0.04147627 | E35: =(10.5*11*0.00394)*0.00001639*C35 -> 2.2375792e-05
A37: Input, Output, Waste FOM Metrics (1 cycle, 28-day batch time)
A38: Process Step | B38: Input | C38: Mass (kg) | D38: Volume (m3) | E38: Power (kWe) | F38: Crew Time (CM-h)
A39: 1: Plant Growth | B39: Lettuce seeds | C39: =B20*(1.01/1000000) -> 4.04e-06 | D39: =((4.57*1.524*0.5)/(1000^3))*B20 -> 1.392936e-08 | F39: =B20*(1/10)*(1/60)*1.5 -> 0.01
B40: Water | C40: =D40*1000 -> 14.478333 | D40: =(7.3*B22*28)*0.34*0.001 -> 0.014478333 | F40: =90*4*(1/60)*(1/12.5)*(1/365)*28*B22*1.5 -> 0.011506849
B41: Plant nutrients | C41: =(1.166+(12.406*3))*(1/1000)*D40*1000 -> 0.55573635 | F41: =(20.17/10)*(1/60)*(1/12.5)*B22*28*1.5 -> 0.023531667
B42: Carbon dioxide | C42: =(10.7*B22*28)/1000 -> 0.062416667 | D42: =C42/1.82 -> 0.034294872 | F42: =2.13*365*(1/60)*(1/365)*28*1.5 -> 1.491
B43: Output | C43: Mass (kg) | D43: Volume (m3) | E43: Power (kWe) | F43: Crew Time (CM-h)
B44: Oxygen | C44: =7.78*B22*28*(1/1000) -> 0.045383333 | D44: =C44*(1/1.3) -> 0.034910256
B45: Water (transpiration) | C45: =2.1*B22*28 -> 12.25 | D45: =C45*(1/1000) -> 0.01225
A46: Process Step | B46: Output | C46: Mass (kg) | D46: Volume (m3) | E46: Power (kWe) | F46: Crew Time (CM-h)
...

Sheet TRANSGENIC-TOBACCO
A1: TRANSGENIC-TOBACCO
A3: PTH-Fc Production Input
B4: Qty | C4: Unit | E4: Legend
A5: Therapeutic dosage (injection or oral): | B5: =Assumptions!B8 -> 5 | C5: mg PTH-Fc/wk/CM | E5: User-editable cell
A6: Therapeutic dosage (injection or oral): | B6: =B5 -> 5 | C6: mg PTH-Fc/wk/CM | E6: Not applicable / No data
A7: Avg PTH-Fc production level: | B7: =Assumptions!C18 -> 28.6 | C7: mg PTH-Fc/kg FW
A10: PLANT GROWTH METRICS
A12: Tobacco Harvest and Planting Metrics
A13: Per 1 harvest cycle and 1 CM
B14: Qty | C14: Unit
A15: Number of harvest cycles | B15: =Assumptions!E18 -> 5 | C15: harvest cycles
A16: Biomass at harvest | B16: =(320/16)*(1/0.0929)*(9830000/982000)*(1/1000) -> 2.1550448 | C16: kg FW/m2
A17: Theoretical mass plant at harvest | B17: =(9830000/982000)*(1/1000) -> 0.010010183 | C17: kg FW/plant
A18: Mass plant required for therapeutic dosage | B18: =B6*(1/B7) -> 0.17482517 | C18: kg FW/wk
A19: Number of plants at harvest | B19: =ROUNDUP(B18/B17,0) -> 18 | C19: plants/wk (dose)
A20: Planting area | B20: =B18/B16 -> 0.081123683 | C20: m2
A21: Per 5 harvest cycles and 1 CM
B22: Qty | C22: Unit
A23: Number of plants | B23: =B19*B15 -> 90 | C23: plants
A24: Mass of plants | B24: =B17*B23 -> 0.9009165 | C24: kg FW
A25: Planting area | B25: =B24/B16 -> 0.41805 | C25: m2
A27: System FOM Metrics
A28: Process Step | B28: Equipment | C28: Qty (units) | D28: Mass (kg) | E28: Volume (m3) | F28: Power (kWe) | G28: Crew Time (CM-h)
A29: 1: Plant Growth | B29: Plant growth chamber | C29: 1 | D29: =(101.5-22.9-8.4)*B25 -> 29.34711 | E29: =(1.03-0.25)*B25 -> 0.326079 | F29: =(2.6-2.1-0.075)*B25 -> 0.17767125
B30: Lighting panels | C30: =ROUNDUP(B25*9,0) -> 4 | D30: =0.243*C30 -> 0.972 | E30: =(0.3*0.3*0.001)*C30 -> 0.00036 | F30: =50.7*C30*(1/1000) -> 0.2028
A31: 2: Leaf Harvest | B31: Refrigerator/Freezer | C31: =IF((0.003785*C33*2) <= 0.0187, 1, CEILING((0.003785*C33*2)/0.0187, 1)) -> 1 | D31: =0.75*B18*C31 -> 0.13111888 | E31: =0.00393*B18*C31 -> 0.00068706294 | F31: =0.00033*B18*C31 -> 5.7692308e-05
B32: Harvesting tools (scissors) | C32: =IF(F45 <= 2, 1, CEILING(F45 / 2, 1)) -> 1 | D32: =0.20411*C32/Assumptions!$B$5 -> 0.034018333 | E32: =0.00064416*C32/Assumptions!$B$5 -> 0.00010736 | H32: Shared across crew, divided by crew size (Assumptions!B5)
B33: Harvest collection container (bags) | C33: =ROUNDUP(B18/(85*0.003785),0) -> 1 | D33: =(7.62/250)*(0.45359/1)*C33 -> 0.013825423 | E33: =(10.5*11*0.00394)*0.00001639*C33 -> 7.4585973e-06
A35: Input, Output, Waste FOM Metrics (1 cycle, 35-day batch time)
A36: Process Step | B36: Input | C36: Mass (kg) | D36: Volume (m3) | E36: Power (kWe) | F36: Crew Time (CM-h)
A37: 1: Plant Growth | B37: N. benthamiana seeds | C37: =0.0004288*B19*2 -> 0.0154368 | D37: =(4/3)*PI()*((0.45/2)^3)*(1/1000^3) -> 4.7712938e-11 | F37: =((B19*2)*(1/10)*(1/60)*1.5)+(4.6*(1/(215*2))*1.5) -> 0.10604651
B38: Water | C38: =D38*1000 -> 7.0472143 | D38: =(7.3*B20*35)*0.34*0.001 -> 0.0070472143 | F38: =90*4*(1/60)*(1/12.5)*(1/365)*35*B20*1.5 -> 0.005600868
B39: Plant nutrients | C39: =((1.166+(12.406*3))*(D38*1000))/1000 -> 0.27050028 | F39: =(20.17/10)*(1/60)*(1/12.5)*B20*35*1.5 -> 0.011453853
B40: Carbon dioxide | C40: =(10.7*B20*35)/1000 -> 0.030380819 | D40: =C40/1.82 -> 0.016692758 | F40: =2.13*365*(1/60)*(1/365)*35*1.5 -> 1.86375
B41: Output | C41: Mass (kg) | D41: Volume (m3) | E41: Power (kWe) | F41: Crew Time (CM-h)
B42: Oxygen | C42: =(7.78*B20*35)/1000 -> 0.022089979 | D42: =C42/1.3 -> 0.016992291
B43: Water (transpiration) | C43: =2.1*B20*35 -> 5.9625907 | D43: =C43/1000 -> 0.0059625907
A44: Process Step | B44: Output | C44: Mass (kg) | D44: Volume (m3) | E44: Power (kWe) | F44: Crew Time (CM-h)
A45: 2: Leaf Harvest | B45: PTH-Fc | C45: =B6/1000000 -> 5e-06 | F45: =(3.97*B20)*(1/60)*1.5 -> 0.0080515255
B46: Plant biomass | C46: =B16*B20 -> 0.17482517 | D46: =C46*(1/60) -> 0.0029137529
...

Sheet GENE GUN
A1: GENE GUN
A3: PTH-Fc Production Input
B4: Qty | C4: Unit | E4: Legend
A5: Therapeutic dosage (injection or oral): | B5: =Assumptions!B8 -> 5 | C5: mg PTH-Fc/wk/CM | E5: User-editable cell
A6: Therapeutic dosage (injection or oral): | B6: =B5 -> 5 | C6: mg PTH-Fc/wk/CM | E6: Not applicable / No data
A7: Avg PTH-Fc production level: | B7: =Assumptions!C19 -> 2.5 | C7: mg PTH-Fc/kg FW
A10: PLANT GROWTH METRICS
A12: Lettuce Harvest and Planting Metrics
A13: Per 1 harvest cycle and 1 CM
B14: Qty | C14: Unit
A15: Number of harvest cycles | B15: 4 | C15: harvest cycles
A16: Edible biomass at harvest | B16: =(131.35*28)/1000 -> 3.6778 | C16: kg FW/m2
A17: Lettuce planting density | B17: 19.2 | C17: plants/m2
A18: Theoretical mass plant at harvest | B18: =B16/B17 -> 0.19155208 | C18: kg FW/plant
A19: Mass plant required for therapeutic dosage | B19: =B6*(1/B7) -> 2 | C19: kg FW/wk
A20: Number of plants at harvest | B20: =ROUNDUP(B19/B18,0) -> 11 | C20: plants/wk (dose)
A21: Actual mass plant at harvest, accounting for dosage | B21: =B18*B20 -> 2.1070729 | C21: kg FW/wk
A22: Planting area | B22: =B21/B16 -> 0.57291667 | C22: m2
A23: Per 4 harvest cycles and 1 CM
B24: Qty | C24: Unit
A25: Number of plants | B25: =B20*B15 -> 44 | C25: plants
A26: Mass of plants | B26: =B18*B25 -> 8.4282917 | C26: kg FW
A27: Planting area | B27: =B26/B16 -> 2.2916667 | C27: m2
A29: System FOM Metrics
A30: Process Step | B30: Equipment | C30: Qty (units) | D30: Mass (kg) | E30: Volume (m3) | F30: Power (kWe) | G30: Crew Time (CM-h)
A31: 1: Plant Growth | B31: Plant growth chamber | C31: 1 | D31: =(101.5-22.9-8.4)*B27 -> 160.875 | E31: =(1.03-0.25)*B27 -> 1.7875 | F31: =(2.6-2.1-0.075)*B27 -> 0.97395833
B32: Lighting panels | C32: =ROUNDUP(B27*9,0) -> 21 | D32: =0.243*C32 -> 5.103 | E32: =(0.3*0.3*0.001)*C32 -> 0.00189 | F32: =50.7*C32*(1/1000) -> 1.0647
A33: 2: Leaf Harvest | B33: Refrigerator/Freezer | C33: =IF((0.003785*C35*2) <= 0.0187, 1, CEILING((0.003785*C35*2)/0.0187, 1)) -> 3 | D33: =0.75*B21*C33 -> 4.7409141 | E33: =0.00393*B21*C33 -> 0.02484239 | F33: =0.00033*B21*C33 -> 0.0020860022
B34: Harvesting tools (scissors) | C34: =IF(F47 <= 2, 1, CEILING(F47 / 2, 1)) -> 1 | D34: =0.20411*C34/Assumptions!$B$5 -> 0.034018333 | E34: =0.00064416*C34/Assumptions!$B$5 -> 0.00010736 | H34: Shared across crew, divided by crew size (Assumptions!B5)
B35: Harvest collection container (bags) | C35: =ROUNDUP(B21/(85*0.003785),0) -> 7 | D35: =(7.62/250)*(0.45359/1)*C35 -> 0.096777962 | E35: =(10.5*11*0.00394)*0.00001639*C35 -> 5.2210181e-05
A37: Input, Output, Waste FOM Metrics (1 cycle, 28-day batch time)
A38: Process Step | B38: Input | C38: Mass (kg) | D38: Volume (m3) | E38: Power (kWe) | F38: Crew Time (CM-h)
A39: 1: Plant Growth | B39: Lettuce seeds | C39: =B20*(1.01/1000000) -> 1.111e-05 | D39: =((4.57*1.524*0.5)/(1000^3))*B20 -> 3.830574e-08 | F39: =B20/(10*60)*1.5 -> 0.0275
B40: Water | C40: =D40*1000 -> 39.815417 | D40: =(7.3*B22*28)*0.34*0.001 -> 0.039815417 | F40: =90*4*(1/60)*(1/12.5)*(1/365)*28*B22*1.5 -> 0.031643836
B41: Plant nutrients | C41: =(1.166+(12.406*3))*(1/1000)*D40*1000 -> 1.528275 | F41: =(20.17/10)*(1/60)*(1/12.5)*B22*28*1.5 -> 0.064712083
B42: Carbon dioxide | C42: =(10.7*B22*28)/1000 -> 0.17164583 | D42: =C42/1.82 -> 0.094310897 | F42: =2.13*365*(1/60)*(1/365)*28*1.5 -> 1.491
B43: Output | C43: Mass (kg) | D43: Volume (m3) | E43: Power (kWe) | F43: Crew Time (CM-h)
B44: Oxygen | C44: =7.78*B22*28*(1/1000) -> 0.12480417 | D44: =C44*(1/1.3) -> 0.096003205
B45: Water (transpiration) | C45: =2.1*B22*28 -> 33.6875 | D45: =C45*(1/1000) -> 0.0336875
A46: Process Step | B46: Output | C46: Mass (kg) | D46: Volume (m3) | E46: Power (kWe) | F46: Crew Time (CM-h)
...

Sheet AGRO
A1: AGRO
A3: PTH-Fc Production Input
B4: Qty | C4: Unit | E4: Legend
A5: Therapeutic dosage (injection or oral): | B5: =Assumptions!B8 -> 5 | C5: mg PTH-Fc/wk/CM | E5: User-editable cell
A6: Therapeutic dosage (injection or oral): | B6: =B5 -> 5 | C6: mg PTH-Fc/wk/CM | E6: Not applicable / No data
A7: Avg PTH-Fc production level: | B7: =Assumptions!C20 -> 373 | C7: mg PTH-Fc/kg FW
A10: PLANT GROWTH METRICS
A12: Tobacco Harvest and Planting Metrics
A13: Per 1 harvest cycle and 1 CM
B14: Qty | C14: Unit
A15: Number of harvest cycles | B15: 5 | C15: harvest cycles
A16: Biomass at harvest | B16: =(320/16)*(1/0.0929)*(9830000/982000)*(1/1000) -> 2.1550448 | C16: kg FW/m2
A17: Theoretical mass plant at harvest | B17: =(9830000/982000)*(1/1000) -> 0.010010183 | C17: kg FW/plant
A18: Mass plant required for therapeutic dosage | B18: =B6*(1/B7) -> 0.013404826 | C18: kg FW/wk
A19: Number of plants at harvest | B19: =ROUNDUP(B18/B17,0) -> 2 | C19: plants/wk (dose)
A20: Planting area | B20: =B18/B16 -> 0.0062202073 | C20: m2
A21: Per 5 harvest cycles and 1 CM
B22: Qty | C22: Unit
A23: Number of plants | B23: =B19*B15 -> 10 | C23: plants
A24: Mass of plants | B24: =B17*B23 -> 0.10010183 | C24: kg FW
A25: Planting area | B25: =B24/B16 -> 0.04645 | C25: m2
A27: System FOM Metrics
A28: Process Step | B28: Equipment | C28: Qty (units) | D28: Mass (kg) | E28: Volume (m3) | F28: Power (kWe) | G28: Crew Time (CM-h)
A29: 1: Plant Growth | B29: Plant growth chamber | C29: 1 | D29: =(101.5-22.9-8.4)*B25 -> 3.26079 | E29: =(1.03-0.25)*B25 -> 0.036231 | F29: =(2.6-2.1-0.075)*B25 -> 0.01974125
B30: Lighting panels | C30: =ROUNDUP(B25*9,0) -> 1 | D30: =0.243*C30 -> 0.243 | E30: =(0.3*0.3*0.001)*C30 -> 9e-05 | F30: =50.7*C30*(1/1000) -> 0.0507
A31: 2: Leaf Harvest | B31: Refrigerator/Freezer | C31: =IF((0.003785*C33*2) <= 0.0187, 1, CEILING((0.003785*C33*2)/0.0187, 1)) -> 1 | D31: =0.75*B18*C31 -> 0.010053619 | E31: =0.00393*B18*C31 -> 5.2680965e-05 | F31: =0.00033*B18*C31 -> 4.4235925e-06
B32: Harvesting tools (scissors) | C32: =IF(F45 <= 2, 1, CEILING(F45 / 2, 1)) -> 1 | D32: =0.20411*C32/Assumptions!$B$5 -> 0.034018333 | E32: =0.00064416*C32/Assumptions!$B$5 -> 0.00010736 | H32: Shared across crew, divided by crew size (Assumptions!B5)
B33: Harvest collection container (bags) | C33: =ROUNDUP(B18/(85*0.003785),0) -> 1 | D33: =(7.62/250)*(0.45359/1)*C33 -> 0.013825423 | E33: =(10.5*11*0.00394)*0.00001639*C33 -> 7.4585973e-06
A35: Input, Output, Waste FOM Metrics (1 cycle, 35-day batch time)
A36: Process Step | B36: Input | C36: Mass (kg) | D36: Volume (m3) | E36: Power (kWe) | F36: Crew Time (CM-h)
A37: 1: Plant Growth | B37: N. benth seeds | C37: =0.0004288*B19*2 -> 0.0017152 | D37: =(4/3)*PI()*((0.45/2)^3)*(1/1000^3) -> 4.7712938e-11 | F37: =((1/10)*(B19*2)*(1/60)*1.5)+(4.6*(1/(215*2))*1.5) -> 0.026046512
B38: Water | C38: =D38*1000 -> 0.54034941 | D38: =(7.3*B20*35)*0.34*0.001 -> 0.00054034941 | F38: =90*4*(1/60)*(1/12.5)*(1/365)*35*B20*1.5 -> 0.00042944993
B39: Plant nutrients | C39: =((1.166+(12.406*3))*(D38*1000))/1000 -> 0.020740772 | F39: =(20.17/10)*(1/60)*(1/12.5)*B20*35*1.5 -> 0.00087823107
B40: Carbon dioxide | C40: =(10.7*B20*35)/1000 -> 0.0023294676 | D40: =C40/1.82 -> 0.0012799273 | F40: =2.13*365*(1/60)*(1/365)*35*1.5 -> 1.86375
B41: Output | C41: Mass (kg) | D41: Volume (m3) | E41: Power (kWe) | F41: Crew Time (CM-h)
B42: Oxygen | C42: =(7.78*B20*35)/1000 -> 0.0016937625 | D42: =C42/1.3 -> 0.0013028942
B43: Water (transpiration) | C43: =2.1*B20*35 -> 0.45718524 | D43: =C43/1000 -> 0.00045718524
A44: Process Step | B44: Output | C44: Mass (kg) | D44: Volume (m3) | E44: Power (kWe) | F44: Crew Time (CM-h)
A45: 2: Leaf Harvest | B45: PTH-Fc | C45: =B6/1000000 -> 5e-06 | F45: =(3.97*B20)/60*1.5 -> 0.00061735558
B46: Plant biomass | C46: =B16*B20 -> 0.013404826 | D46: =C46*(1/60) -> 0.00022341376
...

Sheet VIRAL
A1: VIRAL
A3: PTH-Fc Production Input
B4: =Assumptions!B8 -> 5 | C4: Unit | E4: Legend
A5: Therapeutic dosage (injection or oral): | B5: =Assumptions!B8 -> 5 | C5: mg PTH-Fc/wk/CM | E5: User-editable cell
A6: Therapeutic dosage (injection or oral): | B6: =B5 -> 5 | C6: mg PTH-Fc/wk/CM | E6: Not applicable / No data
A7: Avg PTH-Fc production level: | B7: =Assumptions!C21 -> 300 | C7: mg PTH-Fc/kg FW
A10: PLANT GROWTH METRICS
A12: Tobacco Harvest and Planting Metrics
A13: Per 1 harvest cycle and 1 CM
B14: Qty | C14: Unit
A15: Number of harvest cycles | B15: 5 | C15: harvest cycles
A16: Biomass at harvest | B16: =(320/16)*(1/0.0929)*(9830000/982000)*(1/1000) -> 2.1550448 | C16: kg FW/m2
A17: Theoretical mass plant at harvest | B17: =(9830000/982000)*(1/1000) -> 0.010010183 | C17: kg FW/plant
A18: Mass plant required for therapeutic dosage | B18: =B6*(1/B7) -> 0.016666667 | C18: kg FW/wk
A19: Number of plants at harvest | B19: =ROUNDUP(B18/B17,0) -> 2 | C19: plants/wk (dose)
A20: Planting area | B20: =B18/B16 -> 0.0077337911 | C20: m2
A21: Per 5 harvest cycles and 1 CM
B22: Qty | C22: Unit
A23: Number of plants | B23: =B19*B15 -> 10 | C23: plants
A24: Mass of plants | B24: =B17*B23 -> 0.10010183 | C24: kg FW
A25: Planting area | B25: =B24/B16 -> 0.04645 | C25: m2
A27: System FOM Metrics
A28: Process Step | B28: Equipment | C28: Qty (units) | D28: Mass (kg) | E28: Volume (m3) | F28: Power (kWe) | G28: Crew Time (CM-h)
A29: 1: Plant Growth | B29: Plant growth chamber | C29: 1 | D29: =(101.5-22.9-8.4)*B25 -> 3.26079 | E29: =(1.03-0.25)*B25 -> 0.036231 | F29: =(2.6-2.1-0.075)*B25 -> 0.01974125
B30: Lighting panels | C30: =ROUNDUP(B25*9,0) -> 1 | D30: =0.243*C30 -> 0.243 | E30: =(0.3*0.3*0.001)*C30 -> 9e-05 | F30: =50.7*C30*(1/1000) -> 0.0507
A31: 2: Leaf Harvest | B31: Refrigerator/Freezer | C31: =IF((0.003785*C33*2) <= 0.0187, 1, CEILING((0.003785*C33*2)/0.0187, 1)) -> 1 | D31: =0.75*B18*C31 -> 0.0125 | E31: =0.00393*B18*C31 -> 6.55e-05 | F31: =0.00033*B18*C31 -> 5.5e-06
B32: Harvesting tools (scissors) | C32: =IF(F45 <= 2, 1, CEILING(F45 / 2, 1)) -> 1 | D32: =0.20411*C32/Assumptions!$B$5 -> 0.034018333 | E32: =0.00064416*C32/Assumptions!$B$5 -> 0.00010736 | H32: Shared across crew, divided by crew size (Assumptions!B5)
B33: Harvest collection container (bags) | C33: =ROUNDUP(B18/(85*0.003785),0) -> 1 | D33: =(7.62/250)*(0.45359/1)*C33 -> 0.013825423 | E33: =(10.5*11*0.00394)*0.00001639*C33 -> 7.4585973e-06
A35: Input, Output, Waste FOM Metrics (1 cycle, 28-day batch time)
A36: Process Step | B36: Input | C36: Mass (kg) | D36: Volume (m3) | E36: Power (kWe) | F36: Crew Time (CM-h)
A37: 1: Plant Growth | B37: N. benth seeds | C37: =0.0004288*B19*2 -> 0.0017152 | D37: =(4/3)*PI()*((0.45/2)^3)*(1/1000^3) -> 4.7712938e-11 | F37: =((1/10)*(B19*2)*(1/60)*1.5)+(4.6*(1/(215*2))*1.5) -> 0.026046512
B38: Water | C38: =D38*1000 -> 0.67183443 | D38: =(7.3*B20*35)*0.34*0.001 -> 0.00067183443 | F38: =90*4*(1/60)*(1/12.5)*(1/365)*35*B20*1.5 -> 0.00053394941
B39: Plant nutrients | C39: =((1.166+(12.406*3))*(D38*1000))/1000 -> 0.025787693 | F39: =(20.17/10)*(1/60)*(1/12.5)*B20*35*1.5 -> 0.001091934
B40: Carbon dioxide | C40: =(10.7*B20*35)/1000 -> 0.0028963048 | D40: =C40/1.82 -> 0.0015913762 | F40: =2.13*365*(1/60)*(1/365)*35*1.5 -> 1.86375
B41: Output | C41: Mass (kg) | D41: Volume (m3) | E41: Power (kWe) | F41: Crew Time (CM-h)
B42: Oxygen | C42: =(7.78*B20*35)/1000 -> 0.0021059113 | D42: =C42/1.3 -> 0.0016199318
B43: Water (transpiration) | C43: =2.1*B20*35 -> 0.56843365 | D43: =C43/1000 -> 0.00056843365
A44: Process Step | B44: Output | C44: Mass (kg) | D44: Volume (m3) | E44: Power (kWe) | F44: Crew Time (CM-h)
A45: 2: Leaf Harvest | B45: PTH-Fc | C45: =B6/1000000 -> 5e-06 | F45: =(3.97*B20)/60*1.5 -> 0.00076757877
B46: Plant biomass | C46: =B16*B20 -> 0.016666667 | D46: =C46*(1/60) -> 0.00027777778
...
